Workbook

Sheet Сводка
A1: Сводный трекер текущего ремонта
A2: Сведено 27.10.2026 из трёх выгрузок: годовой план ПТО от 26.10.2026, файл исполнителей от 08.10.2026 с пополнениями от 16.10.2026, Битрикс24 от 27.10.2026. Отметки прежних снимков не используются. Все цифры считаются формулами по листу «Работы», просрочка — на сегодняшнюю дату. Стадии и проблемы — те же, что на странице трекера.
A4: Где мы сейчас — работы плана по стадиям
A5: Стадии идут по ходу работы: не начато → в работе → выполнено, ждёт акта → принято с актом. «Отложено на зиму» и «Нужно решение» — вне хода. Снятые с плана в проценты не входят.
A7: Стадия | B7: Работ | C7: % плана | D7: Из них с проблемой | E7: Какая проблема | I7: Что значит стадия
A8: Не начато | B8: =COUNTIF(Работы!$M$2:$M$450,"Не начато") -> 108 | C8: =IF($B$14=0,0,B8/$B$14) -> 0.24601367 | D8: =COUNTIFS(Работы!$M$2:$M$450,"Не начато",Работы!$P$2:$P$450,">0") -> 75 | E8: месяц плана прошёл | I8: Работа ещё не начата: «Не начато», «Передано исполнителю»
A9: В работе | B9: =COUNTIF(Работы!$M$2:$M$450,"В работе") -> 36 | C9: =IF($B$14=0,0,B9/$B$14) -> 0.082004556 | D9: =COUNTIFS(Работы!$M$2:$M$450,"В работе",Работы!$P$2:$P$450,">0") -> 20 | E9: дольше плана: месяц плана прошёл | I9: Идёт работа: «В работе», «На контроле», «Материал заказан»
A10: Выполнено, ждёт акта | B10: =COUNTIF(Работы!$M$2:$M$450,"Выполнено, ждёт акта") -> 160 | C10: =IF($B$14=0,0,B10/$B$14) -> 0.36446469 | D10: =COUNTIFS(Работы!$M$2:$M$450,"Выполнено, ждёт акта",Работы!$C$2:$C$450,"<"&TODAY()) -> 145 | E10: акт задерживается: месяц плана прошёл | I10: Исполнитель сделал работу, акт ещё не подписан
A11: Принято с актом | B11: =COUNTIF(Работы!$M$2:$M$450,"Принято с актом") -> 110 | C11: =IF($B$14=0,0,B11/$B$14) -> 0.25056948 | E11: — | I11: Работа закрыта актом
A12: Отложено на зиму | B12: =COUNTIF(Работы!$M$2:$M$450,"Отложено на зиму") -> 9 | C12: =IF($B$14=0,0,B12/$B$14) -> 0.020501139 | E12: — | I12: Перенесено на тёплый сезон
A13: Нужно решение | B13: =COUNTIF(Работы!$M$2:$M$450,"Нужно решение") -> 16 | C13: =IF($B$14=0,0,B13/$B$14) -> 0.036446469 | D13: =COUNTIFS(Работы!$M$2:$M$450,"Нужно решение",Работы!$P$2:$P$450,">0") -> 12 | E13: месяц плана прошёл | I13: Работа стоит: «Нужно решение», «Требует уточнения», «Нет статуса», «Голосование ОСС»
A14: Итого в плане | B14: =SUM(B8:B13) -> 439 | C14: =IF(B14=0,0,1) -> 1 | D14: =COUNTIF(Работы!$P$2:$P$450,">0") -> 107 | E14: просрочено всего | I14: Месяц плана прошёл, а работа не начата, в работе или стоит
A15: Снято с плана | B15: =COUNTIF(Работы!$M$2:$M$450,"Снято с плана") -> 10 | I15: В проценты не входит
A17: Итоги | B17: Значение | C17: % плана
A18: Выполнено: ждёт акта + принято с актом | B18: =B10+B11 -> 270 | C18: =IF($B$14=0,0,B18/$B$14) -> 0.61503417
A19: Принято с актом | B19: =B11 -> 110 | C19: =IF($B$14=0,0,B19/$B$14) -> 0.25056948
A20: Оценка плана, ₽ | B20: =SUMIFS(Работы!$I$2:$I$450,Работы!$M$2:$M$450,"<>Снято с плана") -> 36886631
A21: Факт, ₽ | B21: =SUMIFS(Работы!$J$2:$J$450,Работы!$M$2:$M$450,"<>Снято с плана") -> 19306392
A22: Работ без оценки | B22: =B14-COUNTIFS(Работы!$M$2:$M$450,"<>Снято с плана",Работы!$I$2:$I$450,">0") -> 176
A24: Где проблемы — по важности
A25: Красное срывает сроки, жёлтое копится, серое — порядок в данных. Сами работы — фильтром на листе «Работы» (столбец справа подсказывает, по каким столбцам).
A27: Проблема | B27: Работ | C27: Важность | E27: Кто решает | I27: Как найти на листе «Работы»
A28: Не начаты, хотя месяц плана прошёл | B28: =COUNTIFS(Работы!$M$2:$M$450,"Не начато",Работы!$P$2:$P$450,">0") -> 75 | C28: срывает сроки | E28: Исполнитель и ПТО: начать или перенести срок | I28: Стадия «Не начато», «Просрочено, дней» больше 0
A29: В работе дольше плана | B29: =COUNTIFS(Работы!$M$2:$M$450,"В работе",Работы!$P$2:$P$450,">0") -> 20 | C29: срывает сроки | E29: Мастер: дата завершения и что мешает | I29: Стадия «В работе», «Просрочено, дней» больше 0
A30: Работа стоит — нужно решение | B30: =COUNTIF(Работы!$M$2:$M$450,"Нужно решение") -> 16 | C30: срывает сроки | E30: Руководство и ПТО: решить или снять с плана | I30: Стадия «Нужно решение»
A31: Выполнены, но нет акта с прошлых месяцев | B31: =COUNTIFS(Работы!$M$2:$M$450,"Выполнено, ждёт акта",Работы!$C$2:$C$450,"<"&TODAY()) -> 145 | C31: копится | E31: ПТО: оформить и подписать акты | I31: Стадия «Выполнено, ждёт акта», месяц плана прошёл
A32: Открытые работы без мастера участка | B32: =COUNTIFS(Работы!$L$2:$L$450,"(не назначен)",Работы!$M$2:$M$450,"Не начато")+COUNTIFS(Работы!$L$2:$L$450,"(не назначен)",Работы!$M$2:$M$450,"В работе")+COUNTIFS(Работы!$L$2:$L$450,"(не назначен)",Работы!$M$2:$M$450,"Нужно решение") -> 58 | C32: копится | E32: Назначить ответственного мастера | I32: Мастер «(не назначен)», стадия не начато, в работе или нужно решение
A33: Открытые работы без исполнителя | B33: =COUNTIFS(Работы!$K$2:$K$450,"Не распределено",Работы!$M$2:$M$450,"Не начато")+COUNTIFS(Работы!$K$2:$K$450,"Не распределено",Работы!$M$2:$M$450,"В работе")+COUNTIFS(Работы!$K$2:$K$450,"Не распределено",Работы!$M$2:$M$450,"Нужно решение") -> 23 | C33: копится | E33: ПТО: решить, УК или подрядчик | I33: Исполнитель «Не распределено», стадия не начато, в работе или нужно решение
A34: Расходятся план, файл исполнителей и Битрикс24 | B34: =COUNTIF(Работы!$S$2:$S$450,"?*") -> 31 | C34: порядок в данных | E34: Администратор: сверить источники | I34: Столбец «Сверить» не пустой; список — на листе «Сверка»
A35: Выполнено, а в Битрикс24 стадия «Запланировано» | B35: =COUNTIFS(Работы!$M$2:$M$450,"Выполнено, ждёт акта",Работы!$Q$2:$Q$450,"Запланировано")+COUNTIFS(Работы!$M$2:$M$450,"Принято с актом",Работы!$Q$2:$Q$450,"Запланировано") -> 123 | C35: порядок в данных | E35: Ответственный за Битрикс24: обновить стадии | I35: «Стадия Битрикс24» — «Запланировано», стадия выполнено или принято
A37: По месяцам плана
A38: «Просрочен» — месяц закончился, а работы не сделаны. «Без акта» — всё сделано, но не все акты оформлены. «Закрыт» — всё принято с актом.
A40: Месяц плана | B40: В плане | C40: Не начато | D40: В работе | E40: Ждёт акта | F40: Принято | G40: На зиму | H40: Нужно решение | I40: Просрочено | J40: % выполнено | K40: % принято с актом | L40: Состояние месяца
A41: Февраль 2026 | B41: =COUNTIFS(Работы!$B$2:$B$450,"Февраль 2026",Работы!$M$2:$M$450,"<>Снято с плана") -> 7 | C41: =COUNTIFS(Работы!$B$2:$B$450,"Февраль 2026",Работы!$M$2:$M$450,"Не начато") -> 0 | D41: =COUNTIFS(Работы!$B$2:$B$450,"Февраль 2026",Работы!$M$2:$M$450,"В работе") -> 0 | E41: =COUNTIFS(Работы!$B$2:$B$450,"Февраль 2026",Работы!$M$2:$M$450,"Выполнено, ждёт акта") -> 2 | F41: =COUNTIFS(Работы!$B$2:$B$450,"Февраль 2026",Работы!$M$2:$M$450,"Принято с актом") -> 5 | G41: =COUNTIFS(Работы!$B$2:$B$450,"Февраль 2026",Работы!$M$2:$M$450,"Отложено на зиму") -> 0 | H41: =COUNTIFS(Работы!$B$2:$B$450,"Февраль 2026",Работы!$M$2:$M$450,"Нужно решение") -> 0 | I41: =COUNTIFS(Работы!$B$2:$B$450,"Февраль 2026",Работы!$P$2:$P$450,">0") -> 0 | J41: =IF(B41=0,"",(E41+F41)/B41) -> 1 | K41: =IF(B41=0,"",F41/B41) -> 0.71428571 | L41: =IF(DATE(2026,2,28)<TODAY(),IF(C41+D41+H41>0,"просрочен",IF(E41>0,"без акта "&E41,"закрыт")),IF(DATE(2026,2,1)<=TODAY(),"идёт сейчас","впереди")) -> без акта 2
A42: Март 2026 | B42: =COUNTIFS(Работы!$B$2:$B$450,"Март 2026",Работы!$M$2:$M$450,"<>Снято с плана") -> 2 | C42: =COUNTIFS(Работы!$B$2:$B$450,"Март 2026",Работы!$M$2:$M$450,"Не начато") -> 0 | D42: =COUNTIFS(Работы!$B$2:$B$450,"Март 2026",Работы!$M$2:$M$450,"В работе") -> 0 | E42: =COUNTIFS(Работы!$B$2:$B$450,"Март 2026",Работы!$M$2:$M$450,"Выполнено, ждёт акта") -> 0 | F42: =COUNTIFS(Работы!$B$2:$B$450,"Март 2026",Работы!$M$2:$M$450,"Принято с актом") -> 2 | G42: =COUNTIFS(Работы!$B$2:$B$450,"Март 2026",Работы!$M$2:$M$450,"Отложено на зиму") -> 0 | H42: =COUNTIFS(Работы!$B$2:$B$450,"Март 2026",Работы!$M$2:$M$450,"Нужно решение") -> 0 | I42: =COUNTIFS(Работы!$B$2:$B$450,"Март 2026",Работы!$P$2:$P$450,">0") -> 0 | J42: =IF(B42=0,"",(E42+F42)/B42) -> 1 | K42: =IF(B42=0,"",F42/B42) -> 1 | L42: =IF(DATE(2026,3,31)<TODAY(),IF(C42+D42+H42>0,"просрочен",IF(E42>0,"без акта "&E42,"закрыт")),IF(DATE(2026,3,1)<=TODAY(),"идёт сейчас","впереди")) -> закрыт
A43: Апрель 2026 | B43: =COUNTIFS(Работы!$B$2:$B$450,"Апрель 2026",Работы!$M$2:$M$450,"<>Снято с плана") -> 10 | C43: =COUNTIFS(Работы!$B$2:$B$450,"Апрель 2026",Работы!$M$2:$M$450,"Не начато") -> 0 | D43: =COUNTIFS(Работы!$B$2:$B$450,"Апрель 2026",Работы!$M$2:$M$450,"В работе") -> 0 | E43: =COUNTIFS(Работы!$B$2:$B$450,"Апрель 2026",Работы!$M$2:$M$450,"Выполнено, ждёт акта") -> 3 | F43: =COUNTIFS(Работы!$B$2:$B$450,"Апрель 2026",Работы!$M$2:$M$450,"Принято с актом") -> 7 | G43: =COUNTIFS(Работы!$B$2:$B$450,"Апрель 2026",Работы!$M$2:$M$450,"Отложено на зиму") -> 0 | H43: =COUNTIFS(Работы!$B$2:$B$450,"Апрель 2026",Работы!$M$2:$M$450,"Нужно решение") -> 0 | I43: =COUNTIFS(Работы!$B$2:$B$450,"Апрель 2026",Работы!$P$2:$P$450,">0") -> 0 | J43: =IF(B43=0,"",(E43+F43)/B43) -> 1 | K43: =IF(B43=0,"",F43/B43) -> 0.7 | L43: =IF(DATE(2026,4,30)<TODAY(),IF(C43+D43+H43>0,"просрочен",IF(E43>0,"без акта "&E43,"закрыт")),IF(DATE(2026,4,1)<=TODAY(),"идёт сейчас","впереди")) -> без акта 3
A44: Май 2026 | B44: =COUNTIFS(Работы!$B$2:$B$450,"Май 2026",Работы!$M$2:$M$450,"<>Снято с плана") -> 20 | C44: =COUNTIFS(Работы!$B$2:$B$450,"Май 2026",Работы!$M$2:$M$450,"Не начато") -> 0 | D44: =COUNTIFS(Работы!$B$2:$B$450,"Май 2026",Работы!$M$2:$M$450,"В работе") -> 0 | E44: =COUNTIFS(Работы!$B$2:$B$450,"Май 2026",Работы!$M$2:$M$450,"Выполнено, ждёт акта") -> 8 | F44: =COUNTIFS(Работы!$B$2:$B$450,"Май 2026",Работы!$M$2:$M$450,"Принято с актом") -> 12 | G44: =COUNTIFS(Работы!$B$2:$B$450,"Май 2026",Работы!$M$2:$M$450,"Отложено на зиму") -> 0 | H44: =COUNTIFS(Работы!$B$2:$B$450,"Май 2026",Работы!$M$2:$M$450,"Нужно решение") -> 0 | I44: =COUNTIFS(Работы!$B$2:$B$450,"Май 2026",Работы!$P$2:$P$450,">0") -> 0 | J44: =IF(B44=0,"",(E44+F44)/B44) -> 1 | K44: =IF(B44=0,"",F44/B44) -> 0.6 | L44: =IF(DATE(2026,5,31)<TODAY(),IF(C44+D44+H44>0,"просрочен",IF(E44>0,"без акта "&E44,"закрыт")),IF(DATE(2026,5,1)<=TODAY(),"идёт сейчас","впереди")) -> без акта 8
A45: Июнь 2026 | B45: =COUNTIFS(Работы!$B$2:$B$450,"Июнь 2026",Работы!$M$2:$M$450,"<>Снято с плана") -> 22 | C45: =COUNTIFS(Работы!$B$2:$B$450,"Июнь 2026",Работы!$M$2:$M$450,"Не начато") -> 0 | D45: =COUNTIFS(Работы!$B$2:$B$450,"Июнь 2026",Работы!$M$2:$M$450,"В работе") -> 0 | E45: =COUNTIFS(Работы!$B$2:$B$450,"Июнь 2026",Работы!$M$2:$M$450,"Выполнено, ждёт акта") -> 11 | F45: =COUNTIFS(Работы!$B$2:$B$450,"Июнь 2026",Работы!$M$2:$M$450,"Принято с актом") -> 11 | G45: =COUNTIFS(Работы!$B$2:$B$450,"Июнь 2026",Работы!$M$2:$M$450,"Отложено на зиму") -> 0 | H45: =COUNTIFS(Работы!$B$2:$B$450,"Июнь 2026",Работы!$M$2:$M$450,"Нужно решение") -> 0 | I45: =COUNTIFS(Работы!$B$2:$B$450,"Июнь 2026",Работы!$P$2:$P$450,">0") -> 0 | J45: =IF(B45=0,"",(E45+F45)/B45) -> 1 | K45: =IF(B45=0,"",F45/B45) -> 0.5 | L45: =IF(DATE(2026,6,30)<TODAY(),IF(C45+D45+H45>0,"просрочен",IF(E45>0,"без акта "&E45,"закрыт")),IF(DATE(2026,6,1)<=TODAY(),"идёт сейчас","впереди")) -> без акта 11
A46: Июль 2026 | B46: =COUNTIFS(Работы!$B$2:$B$450,"Июль 2026",Работы!$M$2:$M$450,"<>Снято с плана") -> 49 | C46: =COUNTIFS(Работы!$B$2:$B$450,"Июль 2026",Работы!$M$2:$M$450,"Не начато") -> 0 | D46: =COUNTIFS(Работы!$B$2:$B$450,"Июль 2026",Работы!$M$2:$M$450,"В работе") -> 0 | E46: =COUNTIFS(Работы!$B$2:$B$450,"Июль 2026",Работы!$M$2:$M$450,"Выполнено, ждёт акта") -> 16 | F46: =COUNTIFS(Работы!$B$2:$B$450,"Июль 2026",Работы!$M$2:$M$450,"Принято с актом") -> 33 | G46: =COUNTIFS(Работы!$B$2:$B$450,"Июль 2026",Работы!$M$2:$M$450,"Отложено на зиму") -> 0 | H46: =COUNTIFS(Работы!$B$2:$B$450,"Июль 2026",Работы!$M$2:$M$450,"Нужно решение") -> 0 | I46: =COUNTIFS(Работы!$B$2:$B$450,"Июль 2026",Работы!$P$2:$P$450,">0") -> 0 | J46: =IF(B46=0,"",(E46+F46)/B46) -> 1 | K46: =IF(B46=0,"",F46/B46) -> 0.67346939 | L46: =IF(DATE(2026,7,31)<TODAY(),IF(C46+D46+H46>0,"просрочен",IF(E46>0,"без акта "&E46,"закрыт")),IF(DATE(2026,7,1)<=TODAY(),"идёт сейчас","впереди")) -> без акта 16
A47: Август 2026 | B47: =COUNTIFS(Работы!$B$2:$B$450,"Август 2026",Работы!$M$2:$M$450,"<>Снято с плана") -> 26 | C47: =COUNTIFS(Работы!$B$2:$B$450,"Август 2026",Работы!$M$2:$M$450,"Не начато") -> 0 | D47: =COUNTIFS(Работы!$B$2:$B$450,"Август 2026",Работы!$M$2:$M$450,"В работе") -> 0 | E47: =COUNTIFS(Работы!$B$2:$B$450,"Август 2026",Работы!$M$2:$M$450,"Выполнено, ждёт акта") -> 6 | F47: =COUNTIFS(Работы!$B$2:$B$450,"Август 2026",Работы!$M$2:$M$450,"Принято с актом") -> 20 | G47: =COUNTIFS(Работы!$B$2:$B$450,"Август 2026",Работы!$M$2:$M$450,"Отложено на зиму") -> 0 | H47: =COUNTIFS(Работы!$B$2:$B$450,"Август 2026",Работы!$M$2:$M$450,"Нужно решение") -> 0 | I47: =COUNTIFS(Работы!$B$2:$B$450,"Август 2026",Работы!$P$2:$P$450,">0") -> 0 | J47: =IF(B47=0,"",(E47+F47)/B47) -> 1 | K47: =IF(B47=0,"",F47/B47) -> 0.76923077 | L47: =IF(DATE(2026,8,31)<TODAY(),IF(C47+D47+H47>0,"просрочен",IF(E47>0,"без акта "&E47,"закрыт")),IF(DATE(2026,8,1)<=TODAY(),"идёт сейчас","впереди")) -> без акта 6
...

Sheet Работы
A1: № | B1: Месяц плана | C1: Срок (конец месяца) | D1: Адрес | E1: Управляющая компания | F1: Работа | G1: Вид работ | H1: Основание | I1: Оценка, ₽ | J1: Факт, ₽ | K1: Исполнитель | L1: Мастер участка | M1: Стадия | N1: Статус | O1: Акт | P1: Просрочено, дней | Q1: Стадия Битрикс24 | R1: Сроки Битрикс24 | S1: Сверить | T1: Источники статуса | U1: Строка годового плана
A2: 1 | B2: Февраль 2026 | C2: 46081 | D2: Аблукова ул, 83 | E2: УК «СВ» | F2: Установка ТРЖ, 6 шт. | G2: ТРЖ | H2: На основании протокола №20251100115306 от 18.12.2025 | I2: 600000 | J2: 732490.26 | K2: Не распределено | L2: (не назначен) | M2: =IFERROR(VLOOKUP(N2,Словарь!$A$2:$B$15,2,FALSE()),"Нужно решение") -> Принято с актом | N2: Принято, акт есть | O2: есть | P2: =IF(AND(OR(M2="Не начато",M2="В работе",M2="Нужно решение"),C2<TODAY()),TODAY()-C2,"") | T2: 26.10: Принято, акт есть | U2: 8
A3: 2 | B3: Февраль 2026 | C3: 46081 | D3: Аблукова ул, 83 | E3: УК «СВ» | F3: Спил и обрезка деревьев на придомовой территории | G3: Благоустройство | H3: На основании протокола №20251100115306 от 18.12.2025 | I3: 50000 | J3: 19528.71 | K3: УК | L3: Гайдуков А.В. | M3: =IFERROR(VLOOKUP(N3,Словарь!$A$2:$B$15,2,FALSE()),"Нужно решение") -> Принято с актом | N3: Принято, акт есть | O3: есть | P3: =IF(AND(OR(M3="Не начато",M3="В работе",M3="Нужно решение"),C3<TODAY()),TODAY()-C3,"") | Q3: Успешно | R3: срок 01.02.2026 – 28.02.2026; создана 02.10.2026 | T3: 08.10: Выполнено, акта нет → 26.10: Принято, акт есть → 27.10 Битрикс: Принято, акт есть | U3: 9
A4: 3 | B4: Февраль 2026 | C4: 46081 | D4: Верхнеполевая ул, 21 | E4: УК «СВ» | F4: Установка светильников подъезд 1,2, 32 шт. | G4: Электрика | H4: На основании заявления №4214/ОС от 30.12.2025 | I4: 64000 | K4: УК | L4: Шарафутдинов Р.Р. | M4: =IFERROR(VLOOKUP(N4,Словарь!$A$2:$B$15,2,FALSE()),"Нужно решение") -> Выполнено, ждёт акта | N4: Выполнено, акта нет | O4: нет | P4: =IF(AND(OR(M4="Не начато",M4="В работе",M4="Нужно решение"),C4<TODAY()),TODAY()-C4,"") | Q4: Успешно | R4: срок 01.02.2026 – 28.02.2026; создана 02.10.2026 | T4: 08.10: Выполнено, акта нет → 26.10: Выполнено, акта нет → 27.10 Битрикс: Выполнено, акта нет | U4: 10
A5: 4 | B5: Февраль 2026 | C5: 46081 | D5: Минаева ул, 5 | E5: УК «СВ» | F5: Установка светильников датчиков движения в боксах, 90 шт. | G5: Электрика | I5: 201265.04 | J5: 201265.04 | K5: Не распределено | L5: Сандюк Ю.В. | M5: =IFERROR(VLOOKUP(N5,Словарь!$A$2:$B$15,2,FALSE()),"Нужно решение") -> Принято с актом | N5: Принято, акт есть | O5: есть (КС-2 в Битрикс24) | P5: =IF(AND(OR(M5="Не начато",M5="В работе",M5="Нужно решение"),C5<TODAY()),TODAY()-C5,"") | Q5: Успешно | R5: срок 01.02.2026 – 28.02.2026; создана 02.10.2026 | T5: 08.10: Выполнено, акта нет → 26.10: Принято, акт есть → 27.10 Битрикс: Принято, акт есть | U5: 11
A6: 5 | B6: Февраль 2026 | C6: 46081 | D6: Полбина пр-д, 4 | E6: УК «СВ» | F6: Установка зонтов над ВК подъезд №1 | G6: Подъезды | I6: 50000 | J6: 7750 | K6: Не распределено | L6: (не назначен) | M6: =IFERROR(VLOOKUP(N6,Словарь!$A$2:$B$15,2,FALSE()),"Нужно решение") -> Принято с актом | N6: Принято, акт есть | O6: есть (КС-2 в Битрикс24) | P6: =IF(AND(OR(M6="Не начато",M6="В работе",M6="Нужно решение"),C6<TODAY()),TODAY()-C6,"") | Q6: Успешно | R6: срок 02.10.2026 – 02.10.2026; создана 02.10.2026 | T6: 08.10: Выполнено, акта нет → 26.10: Принято, акт есть → 27.10 Битрикс: Принято, акт есть | U6: 12
A7: 6 | B7: Февраль 2026 | C7: 46081 | D7: Поливенская ул, 29 | E7: УК «СВ» | F7: Замена ОДПУ ХВС | G7: Приборы учёта | H7: На основании заявления №964/ОС от 23.12.2025 года | K7: Не распределено | L7: Зеленцов А.В. | M7: =IFERROR(VLOOKUP(N7,Словарь!$A$2:$B$15,2,FALSE()),"Нужно решение") -> Снято с плана | N7: Снято | P7: =IF(AND(OR(M7="Не начато",M7="В работе",M7="Нужно решение"),C7<TODAY()),TODAY()-C7,"") | Q7: Отказано | R7: срок 01.02.2026 – 28.02.2026; создана 02.10.2026 | T7: 08.10: Снято → 26.10: Снято → 27.10 Битрикс: Снято · План: Отказ | U7: 13
A8: 7 | B8: Февраль 2026 | C8: 46081 | D8: Пушкарева ул, 40 | E8: УК «СВ» | F8: Уборка подвала | G8: Санитарное содержание | H8: На основании акта обследования от 27.11.2025 | I8: 20000 | K8: УК | L8: Евграфов С.В. | M8: =IFERROR(VLOOKUP(N8,Словарь!$A$2:$B$15,2,FALSE()),"Нужно решение") -> Выполнено, ждёт акта | N8: Выполнено, акта нет | O8: передан в ПТО | P8: =IF(AND(OR(M8="Не начато",M8="В работе",M8="Нужно решение"),C8<TODAY()),TODAY()-C8,"") | Q8: Успешно | R8: срок 01.02.2026 – 28.02.2026; создана 02.10.2026 | T8: 08.10: Выполнено, акта нет → 26.10: Выполнено, акта нет → 27.10 Битрикс: Выполнено, акта нет | U8: 14
A9: 8 | B9: Февраль 2026 | C9: 46081 | D9: Уютная ул, 10 | E9: УК «Союз» | F9: Ремонт лежака системы КНС в подвале | G9: Инженерные сети | I9: 55000 | J9: 94925 | K9: Не распределено | L9: Зеленцов А.В. | M9: =IFERROR(VLOOKUP(N9,Словарь!$A$2:$B$15,2,FALSE()),"Нужно решение") -> Принято с актом | N9: Принято, акт есть | O9: есть (КС-2 в Битрикс24) | P9: =IF(AND(OR(M9="Не начато",M9="В работе",M9="Нужно решение"),C9<TODAY()),TODAY()-C9,"") | Q9: Успешно | R9: срок 01.02.2026 – 28.02.2026; создана 02.10.2026 | T9: 08.10: Выполнено, акта нет → 26.10: Принято, акт есть → 27.10 Битрикс: Принято, акт есть | U9: 15
A10: 9 | B10: Март 2026 | C10: 46112 | D10: Кузнецова ул, 6 | E10: УК «СВ» | F10: Ремонт л/площадки 2,3,14 этаж | G10: Благоустройство | I10: 400000 | J10: 379200.66 | K10: Не распределено | L10: Сандюк Ю.В. | M10: =IFERROR(VLOOKUP(N10,Словарь!$A$2:$B$15,2,FALSE()),"Нужно решение") -> Принято с актом | N10: Принято, акт есть | O10: есть (КС-2 в Битрикс24) | P10: =IF(AND(OR(M10="Не начато",M10="В работе",M10="Нужно решение"),C10<TODAY()),TODAY()-C10,"") | Q10: Успешно | R10: срок 01.03.2026 – 31.03.2026; создана 02.10.2026 | T10: 08.10: Выполнено, акта нет → 26.10: Принято, акт есть → 27.10 Битрикс: Принято, акт есть | U10: 18
A11: 10 | B11: Март 2026 | C11: 46112 | D11: Любови Шевцовой ул 54Б корп. 3 | E11: УК «СВ» | F11: Ремонт л/к стен и потолков 9-10 эт. | G11: Подъезды | H11: На основании заявления №4090/ОС от 18.12.2025 года | I11: 234873.82 | J11: 234873.82 | K11: Не распределено | L11: (не назначен) | M11: =IFERROR(VLOOKUP(N11,Словарь!$A$2:$B$15,2,FALSE()),"Нужно решение") -> Принято с актом | N11: Принято, акт есть | O11: есть (КС-2 в Битрикс24) | P11: =IF(AND(OR(M11="Не начато",M11="В работе",M11="Нужно решение"),C11<TODAY()),TODAY()-C11,"") | Q11: Успешно | R11: срок 01.03.2026 – 31.03.2026; создана 02.10.2026 | T11: 08.10: Выполнено, акта нет → 26.10: Принято, акт есть → 27.10 Битрикс: Принято, акт есть | U11: 19
A12: 11 | B12: Апрель 2026 | C12: 46142 | D12: Артема ул, 25 | E12: УК «СВ» | F12: Перенос скамеек | G12: Прочее | H12: На основании заявления 3849 | K12: Не распределено | L12: Гайдуков А.В. | M12: =IFERROR(VLOOKUP(N12,Словарь!$A$2:$B$15,2,FALSE()),"Нужно решение") -> Принято с актом | N12: Принято, акт есть | O12: есть | P12: =IF(AND(OR(M12="Не начато",M12="В работе",M12="Нужно решение"),C12<TODAY()),TODAY()-C12,"") | Q12: Успешно | R12: срок 01.04.2026 – 30.04.2026; создана 02.10.2026 | T12: 08.10: Выполнено, акта нет → 26.10: Принято, акт есть → 27.10 Битрикс: Принято, акт есть | U12: 22
A13: 12 | B13: Апрель 2026 | C13: 46142 | D13: Артема ул, 43 | E13: УК «СВ» | F13: Ремонт прилигания козырьков подъезд №2 | G13: Кровля и козырьки | H13: на основании акта обследования о 01.04.2026 | I13: 7000 | J13: 7994.31 | K13: Не распределено | L13: Гайдуков А.В. | M13: =IFERROR(VLOOKUP(N13,Словарь!$A$2:$B$15,2,FALSE()),"Нужно решение") -> Принято с актом | N13: Принято, акт есть | O13: есть (КС-2 в Битрикс24) | P13: =IF(AND(OR(M13="Не начато",M13="В работе",M13="Нужно решение"),C13<TODAY()),TODAY()-C13,"") | Q13: Успешно | R13: срок 01.04.2026 – 30.04.2026; создана 02.10.2026 | T13: 08.10: Выполнено, акта нет → 26.10: Принято, акт есть → 27.10 Битрикс: Принято, акт есть | U13: 23
A14: 13 | B14: Апрель 2026 | C14: 46142 | D14: Доватора ул, 14А | E14: УК «СВ» | F14: Ремонт МПШ кв.№87 (8 904-191-18-55) | G14: Фасад и МПШ | H14: на основании акта обследования от 03.03.2026 | I14: 45000 | J14: 89320 | K14: Не распределено | L14: (не назначен) | M14: =IFERROR(VLOOKUP(N14,Словарь!$A$2:$B$15,2,FALSE()),"Нужно решение") -> Принято с актом | N14: Принято, акт есть | O14: есть (КС-2 в Битрикс24) | P14: =IF(AND(OR(M14="Не начато",M14="В работе",M14="Нужно решение"),C14<TODAY()),TODAY()-C14,"") | Q14: Успешно | R14: срок 01.04.2026 – 30.04.2026; создана 02.10.2026 | T14: 08.10: Выполнено, акта нет → 26.10: Принято, акт есть → 27.10 Битрикс: Принято, акт есть | U14: 24
A15: 14 | B15: Апрель 2026 | C15: 46142 | D15: Доватора ул, 14А | E15: УК «СВ» | F15: Установка лавочек подъезд №3 | G15: Благоустройство | H15: личный прием граждан | I15: 7500 | J15: 29806.52 | K15: Не распределено | L15: (не назначен) | M15: =IFERROR(VLOOKUP(N15,Словарь!$A$2:$B$15,2,FALSE()),"Нужно решение") -> Принято с актом | N15: Принято, акт есть | O15: есть (КС-2 в Битрикс24) | P15: =IF(AND(OR(M15="Не начато",M15="В работе",M15="Нужно решение"),C15<TODAY()),TODAY()-C15,"") | Q15: Успешно | R15: срок 01.04.2026 – 30.04.2026; создана 02.10.2026 | T15: 08.10: Выполнено, акта нет → 26.10: Принято, акт есть → 27.10 Битрикс: Принято, акт есть | U15: 25
A16: 15 | B16: Апрель 2026 | C16: 46142 | D16: Маяковского ул, 11/47 | E16: УК «СВ» | F16: Ремонт температурного шва подъезд №1 | G16: Благоустройство | H16: На основании заявления №3177/ОС от 24.09.2025 | I16: 22500 | K16: Подрядчики | L16: Зеленцов А.В. | M16: =IFERROR(VLOOKUP(N16,Словарь!$A$2:$B$15,2,FALSE()),"Нужно решение") -> Выполнено, ждёт акта | N16: Выполнено, акта нет | O16: нет | P16: =IF(AND(OR(M16="Не начато",M16="В работе",M16="Нужно решение"),C16<TODAY()),TODAY()-C16,"") | Q16: Успешно | R16: срок 01.04.2026 – 30.04.2026; создана 02.10.2026 | T16: 08.10: Выполнено, акта нет → 26.10: Выполнено, акта нет → 27.10 Битрикс: Выполнено, акта нет | U16: 26
A17: 16 | B17: Апрель 2026 | C17: 46142 | D17: Полбина пр-д, 4 | E17: УК «СВ» | F17: Ремонт примыканий ДВК к кровли над кв.№39 | G17: Кровля и козырьки | H17: На основании акта обследования от 13.03.2026 | I17: 70000 | K17: УК | L17: Алиев Р.Р. | M17: =IFERROR(VLOOKUP(N17,Словарь!$A$2:$B$15,2,FALSE()),"Нужно решение") -> Выполнено, ждёт акта | N17: Выполнено, акта нет | O17: передан в ПТО | P17: =IF(AND(OR(M17="Не начато",M17="В работе",M17="Нужно решение"),C17<TODAY()),TODAY()-C17,"") | Q17: Успешно | R17: срок 01.04.2026 – 30.04.2026; создана 02.10.2026 | T17: 08.10: Выполнено, акта нет → 26.10: Выполнено, акта нет → 27.10 Битрикс: Выполнено, акта нет | U17: 27
A18: 17 | B18: Апрель 2026 | C18: 46142 | D18: Пушкарева ул, 8А | E18: УК «СВ» | F18: Ремонт крылец, восстановление обшивки с торца по гарантии | G18: Благоустройство | H18: На основании ранее написанного заявления (в план поставили после личного приема ) | I18: 1000 | K18: УК | L18: Евграфов С.В. | M18: =IFERROR(VLOOKUP(N18,Словарь!$A$2:$B$15,2,FALSE()),"Нужно решение") -> Выполнено, ждёт акта | N18: Выполнено, акта нет | O18: передан в ПТО | P18: =IF(AND(OR(M18="Не начато",M18="В работе",M18="Нужно решение"),C18<TODAY()),TODAY()-C18,"") | Q18: Успешно | R18: срок 01.04.2026 – 30.04.2026; создана 02.10.2026 | T18: 08.10: Выполнено, акта нет → 26.10: Выполнено, акта нет → 27.10 Битрикс: Выполнено, акта нет | U18: 28
A19: 18 | B19: Апрель 2026 | C19: 46142 | D19: Пушкарева ул, 8А | E19: УК «СВ» | F19: Ремонт л/марша 1-6 подъезд (недостающие прутья) | G19: Подъезды | H19: Личный прием | I19: 5000 | J19: 3303.85 | K19: Не распределено | L19: (не назначен) | M19: =IFERROR(VLOOKUP(N19,Словарь!$A$2:$B$15,2,FALSE()),"Нужно решение") -> Принято с актом | N19: Принято, акт есть | O19: есть (КС-2 в Битрикс24) | P19: =IF(AND(OR(M19="Не начато",M19="В работе",M19="Нужно решение"),C19<TODAY()),TODAY()-C19,"") | Q19: Успешно | R19: срок 01.04.2026 – 16.10.2026; создана 02.10.2026 | T19: 26.10: Принято, акт есть → 27.10 Битрикс: Принято, акт есть | U19: 29
A20: 19 | B20: Апрель 2026 | C20: 46142 | D20: Радищева ул, 126 | E20: УК «СВ» | F20: Замена насоса станции ХВС | G20: Инженерные сети | H20: На основании заявления №55/ОС от 14.01.2026 | I20: 60000 | J20: 51000 | K20: Не распределено | L20: (не назначен) | M20: =IFERROR(VLOOKUP(N20,Словарь!$A$2:$B$15,2,FALSE()),"Нужно решение") -> Принято с актом | N20: Принято, акт есть | O20: есть (КС-2 в Битрикс24) | P20: =IF(AND(OR(M20="Не начато",M20="В работе",M20="Нужно решение"),C20<TODAY()),TODAY()-C20,"") | Q20: Успешно | R20: срок 01.04.2026 – 30.04.2026; создана 02.10.2026 | T20: 08.10: Выполнено, акта нет → 26.10: Принято, акт есть → 27.10 Битрикс: Принято, акт есть | U20: 30
A21: 20 | B21: Апрель 2026 | C21: 46142 | D21: Циолковского ул, 5 | E21: УК «Союз» | F21: Прочистка выпуска канализации 2 шт. | G21: Инженерные сети | H21: На основании протокола №20260100137722 | I21: 12000 | J21: 12000 | K21: Не распределено | L21: Зеленцов А.В. | M21: =IFERROR(VLOOKUP(N21,Словарь!$A$2:$B$15,2,FALSE()),"Нужно решение") -> Принято с актом | N21: Принято, акт есть | O21: есть (КС-2 в Битрикс24) | P21: =IF(AND(OR(M21="Не начато",M21="В работе",M21="Нужно решение"),C21<TODAY()),TODAY()-C21,"") | Q21: Успешно | R21: срок 01.04.2026 – 30.04.2026; создана 02.10.2026 | T21: 08.10: Выполнено, акта нет → 26.10: Принято, акт есть → 27.10 Битрикс: Принято, акт есть | U21: 31
A22: 21 | B22: Май 2026 | C22: 46173 | D22: Аблукова ул, 43А | E22: УК «СВ» | F22: Завоз песка | G22: Благоустройство | H22: На основании заявления №1593/ОС от 12.05.2026 | K22: УК | L22: Гайдуков А.В. | M22: =IFERROR(VLOOKUP(N22,Словарь!$A$2:$B$15,2,FALSE()),"Нужно решение") -> Выполнено, ждёт акта | N22: Выполнено, акта нет | O22: передан в ПТО | P22: =IF(AND(OR(M22="Не начато",M22="В работе",M22="Нужно решение"),C22<TODAY()),TODAY()-C22,"") | Q22: Успешно | R22: срок 01.05.2026 – 31.05.2026; создана 02.10.2026 | T22: 08.10: Выполнено, акта нет → 26.10: Выполнено, акта нет → 27.10 Битрикс: Выполнено, акта нет | U22: 35
A23: 22 | B23: Май 2026 | C23: 46173 | D23: Аблукова ул, 83 | E23: УК «СВ» | F23: Ремонт кровли лоджии кв. №36 | G23: Кровля и козырьки | H23: На основании акта обследования от 14.01.2026 года | I23: 23433.94 | J23: 23433.94 | K23: Не распределено | L23: Гайдуков А.В. | M23: =IFERROR(VLOOKUP(N23,Словарь!$A$2:$B$15,2,FALSE()),"Нужно решение") -> Принято с актом | N23: Принято, акт есть | O23: есть (КС-2 в Битрикс24) | P23: =IF(AND(OR(M23="Не начато",M23="В работе",M23="Нужно решение"),C23<TODAY()),TODAY()-C23,"") | Q23: Успешно | R23: срок 01.05.2026 – 31.05.2026; создана 02.10.2026 | T23: 08.10: Выполнено, акта нет → 26.10: Принято, акт есть → 27.10 Битрикс: Принято, акт есть | U23: 34
A24: 23 | B24: Май 2026 | C24: 46173 | D24: Артема ул, 23 | E24: УК «СВ» | F24: Косметический ремонт балконов незадымляемой л/клетки | G24: Фасад и МПШ | H24: На основании протокола №20251100107454 от 01.12.2025 | I24: 367220 | J24: 367220 | K24: Не распределено | L24: Гайдуков А.В. | M24: =IFERROR(VLOOKUP(N24,Словарь!$A$2:$B$15,2,FALSE()),"Нужно решение") -> Принято с актом | N24: Принято, акт есть | O24: есть (КС-2 в Битрикс24) | P24: =IF(AND(OR(M24="Не начато",M24="В работе",M24="Нужно решение"),C24<TODAY()),TODAY()-C24,"") | Q24: Успешно | R24: срок 01.05.2026 – 31.05.2026; создана 02.10.2026 | T24: 08.10: Выполнено, акта нет → 26.10: Принято, акт есть → 27.10 Битрикс: Принято, акт есть | U24: 36
A25: 24 | B25: Май 2026 | C25: 46173 | D25: Артема ул, 43 | E25: УК «СВ» | F25: Установка лавочек подъезд №5 | G25: Благоустройство | H25: На основании заявления №1437/ЗКС А от 28.04.2026 | I25: 15000 | J25: 84188.94 | K25: Не распределено | L25: Гайдуков А.В. | M25: =IFERROR(VLOOKUP(N25,Словарь!$A$2:$B$15,2,FALSE()),"Нужно решение") -> Принято с актом | N25: Принято, акт есть | O25: есть (КС-2 в Битрикс24) | P25: =IF(AND(OR(M25="Не начато",M25="В работе",M25="Нужно решение"),C25<TODAY()),TODAY()-C25,"") | Q25: Успешно | R25: срок 01.05.2026 – 31.05.2026; создана 02.10.2026 | T25: 08.10: Выполнено, акта нет → 26.10: Принято, акт есть → 27.10 Битрикс: Принято, акт есть | U25: 37
A26: 25 | B26: Май 2026 | C26: 46173 | D26: Докучаева ул, 12 | E26: УК «СВ» | F26: Замена окон ПВХ поъезд №1-3 | G26: Прочее | I26: 470000 | J26: 470000 | K26: Не распределено | L26: (не назначен) | M26: =IFERROR(VLOOKUP(N26,Словарь!$A$2:$B$15,2,FALSE()),"Нужно решение") -> Принято с актом | N26: Принято, акт есть | O26: есть (КС-2 в Битрикс24) | P26: =IF(AND(OR(M26="Не начато",M26="В работе",M26="Нужно решение"),C26<TODAY()),TODAY()-C26,"") | Q26: Успешно | R26: срок 01.05.2026 – 31.05.2026; создана 02.10.2026 | T26: 08.10: Выполнено, акта нет → 26.10: Принято, акт есть → 27.10 Битрикс: Принято, акт есть | U26: 38
A27: 26 | B27: Май 2026 | C27: 46173 | D27: Карла Либкнехта ул, 22 | E27: УК «СВ» | F27: Установка оконных блоков подъезд №1-5 | G27: Подъезды | I27: 105000 | K27: Подрядчики | L27: Сандюк Ю.В. | M27: =IFERROR(VLOOKUP(N27,Словарь!$A$2:$B$15,2,FALSE()),"Нужно решение") -> Выполнено, ждёт акта | N27: Выполнено, акта нет | O27: нет | P27: =IF(AND(OR(M27="Не начато",M27="В работе",M27="Нужно решение"),C27<TODAY()),TODAY()-C27,"") | Q27: Успешно | R27: срок 01.05.2026 – 31.05.2026; создана 02.10.2026 | T27: 08.10: Выполнено, акта нет → 26.10: Выполнено, акта нет → 27.10 Битрикс: Выполнено, акта нет | U27: 39
A28: 27 | B28: Май 2026 | C28: 46173 | D28: Любови Шевцовой ул, 54Б корп. 4 | E28: УК «СВ» | F28: Ремонт кровли кв.№40а | G28: Кровля и козырьки | H28: На основании акта обследования от 05.02.2026 | I28: 50000 | J28: 37105.7 | K28: Не распределено | L28: (не назначен) | M28: =IFERROR(VLOOKUP(N28,Словарь!$A$2:$B$15,2,FALSE()),"Нужно решение") -> Принято с актом | N28: Принято, акт есть | O28: есть (КС-2 в Битрикс24) | P28: =IF(AND(OR(M28="Не начато",M28="В работе",M28="Нужно решение"),C28<TODAY()),TODAY()-C28,"") | Q28: Успешно | R28: срок 02.10.2026 – 02.10.2026; создана 02.10.2026 | T28: 08.10: Выполнено, акта нет → 26.10: Принято, акт есть → 27.10 Битрикс: Принято, акт есть | U28: 40
A29: 28 | B29: Май 2026 | C29: 46173 | D29: Московское шоссе, 100 | E29: УК «СВ» | F29: Ремонт кровли лоджии с заменой отлива и устройства примыканий к парапету кв. №286 | G29: Кровля и козырьки | H29: На основани акта обследования от 26.02.2026 | I29: 60000 | J29: 46000 | K29: Не распределено | L29: (не назначен) | M29: =IFERROR(VLOOKUP(N29,Словарь!$A$2:$B$15,2,FALSE()),"Нужно решение") -> Принято с актом | N29: Принято, акт есть | O29: есть (КС-2 в Битрикс24) | P29: =IF(AND(OR(M29="Не начато",M29="В работе",M29="Нужно решение"),C29<TODAY()),TODAY()-C29,"") | Q29: Успешно | R29: срок 01.05.2026 – 31.05.2026; создана 02.10.2026 | T29: 08.10: Выполнено, акта нет → 26.10: Принято, акт есть → 27.10 Битрикс: Принято, акт есть | U29: 41
A30: 29 | B30: Май 2026 | C30: 46173 | D30: Орджоникидзе ул, 55 | E30: УК «СВ» | F30: Ремонт кровли кв.№59,60,80 | G30: Кровля и козырьки | H30: Обращение ГЖИ | I30: 150000 | K30: УК | L30: Зеленцов А.В. | M30: =IFERROR(VLOOKUP(N30,Словарь!$A$2:$B$15,2,FALSE()),"Нужно решение") -> Выполнено, ждёт акта | N30: Выполнено, акта нет | O30: нет | P30: =IF(AND(OR(M30="Не начато",M30="В работе",M30="Нужно решение"),C30<TODAY()),TODAY()-C30,"") | Q30: Запланировано | R30: срок 01.05.2026 – 31.05.2026; создана 02.10.2026 | T30: 08.10: Выполнено, акта нет → 26.10: Выполнено, акта нет | U30: 42
A31: 30 | B31: Май 2026 | C31: 46173 | D31: Орлова ул, 27 | E31: УК «СВ» | F31: Ремонт скамейки, подъезд №6 | G31: Благоустройство | H31: На основании заявления №1036/ОС от 30.03.2026 | K31: Не распределено | L31: Шарафутдинов Р.Р. | M31: =IFERROR(VLOOKUP(N31,Словарь!$A$2:$B$15,2,FALSE()),"Нужно решение") -> Принято с актом | N31: Принято, акт есть | O31: есть | P31: =IF(AND(OR(M31="Не начато",M31="В работе",M31="Нужно решение"),C31<TODAY()),TODAY()-C31,"") | Q31: Успешно | R31: срок 01.05.2026 – 31.05.2026; создана 02.10.2026 | T31: 08.10: Выполнено, акта нет → 26.10: Принято, акт есть → 27.10 Битрикс: Принято, акт есть · Исполнитель 08.10: По содержанию | U31: 43
A32: 31 | B32: Май 2026 | C32: 46173 | D32: Орлова ул, 27 | E32: УК «СВ» | F32: Установка полусферы на прежнее место к контейнерам | G32: Двери, окна, входные группы | H32: На основании заявления №1036/ОС от 30.03.2026 | K32: Не распределено | L32: Шарафутдинов Р.Р. | M32: =IFERROR(VLOOKUP(N32,Словарь!$A$2:$B$15,2,FALSE()),"Нужно решение") -> Принято с актом | N32: Принято, акт есть | O32: есть | P32: =IF(AND(OR(M32="Не начато",M32="В работе",M32="Нужно решение"),C32<TODAY()),TODAY()-C32,"") | Q32: Успешно | R32: срок 01.05.2026 – 31.05.2026; создана 02.10.2026 | T32: 08.10: Выполнено, акта нет → 26.10: Принято, акт есть → 27.10 Битрикс: Принято, акт есть · Исполнитель 08.10: По содержанию | U32: 44
A33: 32 | B33: Май 2026 | C33: 46173 | D33: Пожарского ул, 29А | E33: УК «СВ» | F33: Ремонт кровли лоджии кв.№45 | G33: Кровля и козырьки | H33: На основании акта обследования от 26.03.2026 года | I33: 40000 | J33: 79331.36 | K33: Не распределено | L33: (не назначен) | M33: =IFERROR(VLOOKUP(N33,Словарь!$A$2:$B$15,2,FALSE()),"Нужно решение") -> Принято с актом | N33: Принято, акт есть | O33: есть (КС-2 в Битрикс24) | P33: =IF(AND(OR(M33="Не начато",M33="В работе",M33="Нужно решение"),C33<TODAY()),TODAY()-C33,"") | Q33: Успешно | R33: срок 01.05.2026 – 31.05.2026; создана 02.10.2026 | T33: 08.10: Выполнено, акта нет → 26.10: Принято, акт есть → 27.10 Битрикс: Принято, акт есть | U33: 45
A34: 33 | B34: Май 2026 | C34: 46173 | D34: Пожарского ул, 29А | E34: УК «СВ» | F34: Покраска МАФ(элементы детской площадки и бордюр) | G34: Благоустройство | H34: На основании заявления №1241/ОС от 14.04.2026 | K34: Не распределено | L34: (не назначен) | M34: =IFERROR(VLOOKUP(N34,Словарь!$A$2:$B$15,2,FALSE()),"Нужно решение") -> Принято с актом | N34: Принято, акт есть | O34: есть | P34: =IF(AND(OR(M34="Не начато",M34="В работе",M34="Нужно решение"),C34<TODAY()),TODAY()-C34,"") | Q34: Успешно | R34: срок 01.05.2026 – 31.05.2026; создана 02.10.2026 | T34: 08.10: Выполнено, акта нет → 26.10: Принято, акт есть → 27.10 Битрикс: Принято, акт есть · Исполнитель 08.10: По содержанию | U34: 46
A35: 34 | B35: Май 2026 | C35: 46173 | D35: Пожарского ул, 29А | E35: УК «СВ» | F35: Завоз песка(предварительно вывезти старыйпесок) | G35: Благоустройство | H35: На основании заявления №1241/ОС от 14.04.2026 | K35: Не распределено | L35: (не назначен) | M35: =IFERROR(VLOOKUP(N35,Словарь!$A$2:$B$15,2,FALSE()),"Нужно решение") -> Принято с актом | N35: Принято, акт есть | O35: есть | P35: =IF(AND(OR(M35="Не начато",M35="В работе",M35="Нужно решение"),C35<TODAY()),TODAY()-C35,"") | Q35: Успешно | R35: срок 01.05.2026 – 31.05.2026; создана 02.10.2026 | T35: 08.10: Выполнено, акта нет → 26.10: Принято, акт есть → 27.10 Битрикс: Принято, акт есть · Исполнитель 08.10: По содержанию | U35: 47
A36: 35 | B36: Май 2026 | C36: 46173 | D36: Поливенская ул, 7 | E36: УК «СВ» | F36: Ремонт наружн. кухонной стены кв.№22 | G36: Прочее | H36: На основании протокола №027/л от 04.04.2024 года. | I36: 25000 | J36: 69400 | K36: Не распределено | L36: Зеленцов А.В. | M36: =IFERROR(VLOOKUP(N36,Словарь!$A$2:$B$15,2,FALSE()),"Нужно решение") -> Принято с актом | N36: Принято, акт есть | O36: есть (КС-2 в Битрикс24) | P36: =IF(AND(OR(M36="Не начато",M36="В работе",M36="Нужно решение"),C36<TODAY()),TODAY()-C36,"") | Q36: Успешно | R36: срок 01.05.2026 – 31.05.2026; создана 02.10.2026 | T36: 08.10: Выполнено, акта нет → 26.10: Принято, акт есть → 27.10 Битрикс: Принято, акт есть · План: Выполнено Шалаев | U36: 48
A37: 36 | B37: Май 2026 | C37: 46173 | D37: Радищева ул, 3 корп. 1 | E37: УК «СВ» | F37: Замена урн, 4 шт | G37: Благоустройство | H37: На основании заявления ПСД | I37: 10000 | K37: УК | L37: Мастер участка (Север) | M37: =IFERROR(VLOOKUP(N37,Словарь!$A$2:$B$15,2,FALSE()),"Нужно решение") -> Выполнено, ждёт акта | N37: Выполнено, акта нет | O37: нет | P37: =IF(AND(OR(M37="Не начато",M37="В работе",M37="Нужно решение"),C37<TODAY()),TODAY()-C37,"") | Q37: Успешно | R37: срок 01.05.2026 – 31.05.2026; создана 02.10.2026 | T37: 08.10: Выполнено, акта нет → 26.10: Выполнено, акта нет → 27.10 Битрикс: Выполнено, акта нет | U37: 49
A38: 37 | B38: Май 2026 | C38: 46173 | D38: Радищева ул, 3 корп. 1 | E38: УК «СВ» | F38: Покраска МАФ ((лавочки;забор; входные двери в дом, подвал и мусорные камеры)) | G38: Двери, окна, входные группы | H38: На основании заявления ПСД | I38: 20000 | K38: УК | L38: Мастер участка (Север) | M38: =IFERROR(VLOOKUP(N38,Словарь!$A$2:$B$15,2,FALSE()),"Нужно решение") -> Выполнено, ждёт акта | N38: Выполнено, акта нет | O38: нет | P38: =IF(AND(OR(M38="Не начато",M38="В работе",M38="Нужно решение"),C38<TODAY()),TODAY()-C38,"") | Q38: Успешно | R38: срок 01.05.2026 – 31.05.2026; создана 02.10.2026 | T38: 08.10: Выполнено, акта нет → 26.10: Выполнено, акта нет → 27.10 Битрикс: Выполнено, акта нет | U38: 50
A39: 38 | B39: Май 2026 | C39: 46173 | D39: Радищева ул, 3 корп. 1 | E39: УК «СВ» | F39: Подштукатурить цементным расвором входы в подвал) | G39: Подъезды | H39: На основании заявления ПСД | I39: 210000 | K39: Подрядчики | L39: (не назначен) | M39: =IFERROR(VLOOKUP(N39,Словарь!$A$2:$B$15,2,FALSE()),"Нужно решение") -> Выполнено, ждёт акта | N39: Выполнено, акта нет | P39: =IF(AND(OR(M39="Не начато",M39="В работе",M39="Нужно решение"),C39<TODAY()),TODAY()-C39,"") | Q39: Успешно | R39: срок 01.05.2026 – 31.05.2026; создана 02.10.2026 | T39: 08.10: Выполнено, акта нет → 26.10: Выполнено, акта нет → 27.10 Битрикс: Выполнено, акта нет | U39: 51
A40: 39 | B40: Май 2026 | C40: 46173 | D40: Терешковой ул, 14 | E40: УК «СВ» | F40: Локальный ремонт кровли кв.№58 | G40: Кровля и козырьки | H40: На основании заявления №1023/ОС | I40: 15000 | K40: УК | L40: Вазюков В.С. | M40: =IFERROR(VLOOKUP(N40,Словарь!$A$2:$B$15,2,FALSE()),"Нужно решение") -> Выполнено, ждёт акта | N40: Выполнено, акта нет | O40: передан в ПТО | P40: =IF(AND(OR(M40="Не начато",M40="В работе",M40="Нужно решение"),C40<TODAY()),TODAY()-C40,"") | Q40: Успешно | R40: срок 01.05.2026 – 31.05.2026; создана 02.10.2026 | T40: 08.10: Выполнено, акта нет → 26.10: Выполнено, акта нет → 27.10 Битрикс: Выполнено, акта нет | U40: 52
...

Sheet Сверка
A1: Адрес | B1: Работа | C1: Месяц | D1: Статус в трекере | E1: Мастер | F1: Что расходится | G1: Решение
A2: Пушкарева ул, 40 | B2: Ремонт подъездов №1-4 | C2: Июль | D2: Выполнено, акта нет | F2: статус расходится: Битрикс24: «В работе», а 26.10 — выполнено, акта нет
A3: Пушкарева ул, 6А | B3: Закупка вазонов, 2 шт | C3: Июль | D3: Принято, акт есть | F3: факт: в плане 8000,00 ₽, у исполнителей 10000,00 ₽
A4: Розы Люксембург ул, 50 | B4: Установка урн 6 шт (3 на детской площадке) | C4: Июль | D4: Выполнено, акта нет | E4: Зеленцов А.В. | F4: статус расходится: Битрикс24: «В работе», а 26.10 — выполнено, акта нет
A5: 50-летия ВЛКСМ пр-т, 3 | B5: Ремонт напольной плитки в подъездах (Сырбаков) | C5: Август | D5: Принято, акт есть | F5: факт: в плане 758676,22 ₽, у исполнителей 743600,00 ₽
A6: Гагарина ул, 11 | B6: Установить дверь на балконе 3-го жтажа (Спецстекло) | C6: Август | D6: Принято, акт есть | F6: факт: в плане 67200,00 ₽, у исполнителей 64200,00 ₽
A7: Аблукова ул, 83 | B7: Ремонт кровли над кв. №107 | C7: Сентябрь | D7: Выполнено, акта нет | E7: Гайдуков А.В. | F7: работа есть только в файле исполнителей, в годовом плане 26.10 её нет
A8: Автозаводская ул, 56 | B8: Перенос вентилей ХВС в подвале | C8: Сентябрь | D8: Требует уточнения | E8: Алиев Р.Р. | F8: исполнитель: в файле исполнителей «Алиев/ПТО» — УК или подрядчик?
A9: Ватутина ул, 26 | B9: Установка радиатора библиотека №25, радиатор в наличии | C9: Сентябрь | D9: Требует уточнения | E9: Зеленцов А.В. | F9: исполнитель: в файле исполнителей «Зеленцов/ПТО» — УК или подрядчик?
A10: Гагарина ул, 31 | B10: Установка металлической двери на цокольном этаже | C10: Сентябрь | D10: Снято | F10: в Битрикс24 другой адрес: «улица Гагарина, 3»
A11: Гагарина ул, 31 | B11: Ремонт наружной стены на 17-м этаже | C11: Сентябрь | D11: Не начато | F11: в Битрикс24 другой адрес: «улица Гагарина, 3»
A12: Доватора ул, 9 | B12: Заамена вводной трубы ХВС (наружка) | C12: Сентябрь | D12: Требует уточнения | E12: Алиев Р.Р. | F12: исполнитель: в файле исполнителей «Алиев/ПТО» — УК или подрядчик?
A13: Нариманова пр-т, 112 | B13: Замена стояка ХВС в кв. №6,12,18,24,30,36,42,48,54 | C13: Сентябрь | D13: На контроле | E13: Зеленцов А.В. | F13: исполнитель: в файле исполнителей «Зеленцов/ПТО» — УК или подрядчик?
A14: Нариманова пр-т, 82 | B14: Частичный ремонт розлива ЦО | C14: Сентябрь | D14: Требует уточнения | E14: Зеленцов А.В. | F14: исполнитель: в файле исполнителей «Зеленцов/ПТО» — УК или подрядчик?
A15: Нариманова пр-т, 97 | B15: замена канализационной трубы и стояков ХВС ,ГВС в кв. №84,88,92 | C15: Сентябрь | D15: Требует уточнения | E15: Мастер участка (Север) | F15: исполнитель: в файле исполнителей «Мастер/ПТО» — УК или подрядчик?
A16: Орджоникидзе ул, 55 | B16: Ремонт кровли | C16: Сентябрь | D16: Выполнено, акта нет | E16: Зеленцов А.В. | F16: работа есть только в файле исполнителей, в годовом плане 26.10 её нет
A17: Орлова ул, 27 | B17: Ремонт отмостки возле 6 подъезда | C17: Сентябрь | D17: Голосование ОСС | E17: Шарафутдинов Р.Р. | F17: в Битрикс24 другой адрес: «улица Орлова, 2»
A18: Пушкарева ул, 74 | B18: Залить битумом щели на отмостках (содержание) | C18: Сентябрь | D18: Выполнено, акта нет | E18: Гайдуков А.В. | F18: в Битрикс24 другой адрес: «улица Пушкарёва, 70»
A19: Пушкарева ул, 74 | B19: Замена окна разбитого входная группа подъезд №1 | C19: Сентябрь | D19: Не начато | F19: в Битрикс24 другой адрес: «улица Пушкарёва, 70»
A20: Пушкарева ул, 74 | B20: Установить фотоэлемент для освещения входа в подъезд №2 | C20: Сентябрь | D20: Не начато | F20: в Битрикс24 другой адрес: «улица Пушкарёва, 70»
A21: Пушкарева ул, 74 | B21: Установка пластиковых калпоков на фановые трубы | C21: Сентябрь | D21: На контроле | E21: Гайдуков А.В. | F21: в Битрикс24 другой адрес: «улица Пушкарёва, 70»
A22: Пушкарева ул, 74 | B22: Закончить кирпичную кладку до потолка входная группа подъезд №1 | C22: Сентябрь | D22: Не начато | F22: в Битрикс24 другой адрес: «улица Пушкарёва, 70»
A23: Пушкарева ул, 74 | B23: Восстановить козырьки коробов вентиляции, 10 шт,сетчатое ограждение, сетчатое ограждение над кв. №162 | C23: Сентябрь | D23: Не начато | F23: в Битрикс24 другой адрес: «улица Пушкарёва, 70»
A24: Пушкарева ул, 74 | B24: Замена трубы ХВС в кв. №66 | C24: Сентябрь | D24: На контроле | E24: Гайдуков А.В. | F24: в Битрикс24 другой адрес: «улица Пушкарёва, 70»
A25: Радищева ул, 126 | B25: Ремонт л/к, два подъезда с 1-й по 2-й этаж (покараска,побелка, плитка напольняа) | C25: Сентябрь | D25: Нет статуса | F25: работа есть только в файле исполнителей, в годовом плане 26.10 её нет
A26: Средний Венец ул, 1 | B26: Ремонт кровли над кв 61,63 | C26: Сентябрь | D26: Выполнено, акта нет | E26: Мастер участка (Север) | F26: работа есть только в файле исполнителей, в годовом плане 26.10 её нет
A27: Автозаводская ул, 28 | B27: Ремонт мягкой кровли лоджии кв. №209 (16 кв.м) | C27: Октябрь | D27: Выполнено, акта нет | E27: Алиев Р.Р. | F27: статус расходится: Битрикс24: «Просрочено», а 08.10 — выполнено, акта нет
A28: Пожарского ул, 29А | B28: Ремонт кровли кв. №59 | C28: Октябрь | D28: Выполнено, акта нет | E28: Алиев Р.Р. | F28: статус расходится: Битрикс24: «В работе», а 08.10 — выполнено, акта нет
A29: Полбина пр-д, 22 | B29: Ремонт МПШ кв.№67 | C29: Октябрь | D29: Не начато | E29: Наумова Т.Ю. | F29: в Битрикс24 другой адрес: «проезд Полбина, 32»
A30: Пушкарева ул, 74 | B30: Ремонт п/сушителя и кварна ГВС в ванной в кв. №258 | C30: Октябрь | D30: В работе | E30: Гайдуков А.В. | F30: в Битрикс24 другой адрес: «улица Пушкарёва, 74/107»
A31: Циолковского ул, 5 | B31: Замена выпуска канализации подъезд №1 | C31: Октябрь | D31: Выполнено, акта нет | E31: Зеленцов А.В. | F31: статус расходится: Битрикс24: «Просрочено», а 08.10 — выполнено, акта нет
A32: Гагарина ул, 31/2А | B32: Установить светильник с датчиком движения на 4-м этаже около мусоропровода | C32: Ноябрь | D32: Не начато | E32: Наумова Т.Ю. | F32: работа есть только в Битрикс24, в годовом плане 26.10 её нет
A34: Столбец «Решение» (жёлтый) заполняет ПТО или администратор трекера, например: «верно по плану», «адрес — Пушкарева 74».

Sheet Словарь
A1: Статус в трекере | B1: Стадия (как на странице трекера) | C1: Может быть просрочена
A2: Не начато | B2: Не начато | C2: да
A3: Передано исполнителю | B3: Не начато | C3: да
A4: В работе | B4: В работе | C4: да
A5: На контроле | B5: В работе | C5: да
A6: Материал заказан | B6: В работе | C6: да
A7: Выполнено, акта нет | B7: Выполнено, ждёт акта
A8: Принято, акт есть | B8: Принято с актом
A9: Отложено на зиму | B9: Отложено на зиму
A10: Нужно решение | B10: Нужно решение | C10: да
A11: Требует уточнения | B11: Нужно решение | C11: да
A12: Нет статуса | B12: Нужно решение | C12: да
A13: Вопрос капремонта | B13: Нужно решение | C13: да
A14: Голосование ОСС | B14: Нужно решение | C14: да
A15: Снято | B15: Снято с плана
A17: Соответствие статусов в источниках и в трекере
A18: Источник | B18: Как записано в источнике | C18: Статус в трекере | D18: Примечание
A19: Годовой план ПТО | B19: зелёная строка | C19: Принято, акт есть
A20: Годовой план ПТО | B20: жёлтая строка, «Выполнено», «Акта нет» | C20: Выполнено, акта нет
A21: Годовой план ПТО | B21: красная строка, «отмена», «отказ» | C21: Снято
A22: Годовой план ПТО | B22: оранжевая строка | C22: (исполнитель УК) | D22: цвет говорит об исполнителе, а не о статусе
A23: Годовой план ПТО | B23: серая строка | C23: (исполнитель — Подрядчики) | D23: цвет говорит об исполнителе, а не о статусе
A24: Файл исполнителей | B24: в столбце исполнителя «ПТО» | C24: (исполнитель — Подрядчики)
A25: Файл исполнителей | B25: в столбце исполнителя мастер или электрик | C25: (исполнитель УК) | D25: работа своими силами
A26: Файл исполнителей | B26: выполнено | C26: Выполнено, акта нет | D26: пока ПТО не подтвердит акт
A27: Файл исполнителей | B27: в работе | C27: В работе
A28: Файл исполнителей | B28: на контроле | C28: На контроле | D28: предложение: заменить на «В работе» с комментарием, что мешает
A29: Файл исполнителей | B29: зима | C29: Отложено на зиму
A30: Файл исполнителей | B30: отказ, отмена | C30: Снято
A31: Файл исполнителей | B31: ????? | C31: Требует уточнения
A32: Файл исполнителей | B32: Акт в ПТО / Акта нет / как подписывать | C32: (поле «Акт») | D32: это состояние акта, а не статус работы
A33: Битрикс24 | B33: Запланировано | C33: не меняет статус | D33: стоит и у выполненных работ — стадии не ведутся
A34: Битрикс24 | B34: В работе, Просрочено, В работе. Утверждена дата | C34: В работе
A35: Битрикс24 | B35: Выполнено, документы не сданы | C35: Выполнено, акта нет
A36: Битрикс24 | B36: Успешно | C36: Принято, акт есть — если есть КС-2 или зелёная строка, иначе «Выполнено, акта нет» | D36: смысл стадии нужно подтвердить
A37: Битрикс24 | B37: Отказано | C37: Снято
A39: Предложение по соответствию — для утверждения (вопрос о едином словаре статусов).
